[[06/03/2020 11:34:33 AM]] Internal Server Error: /GeneratedImage
Traceback (most recent call last):
  File "/Library/Frameworks/Python.framework/Versions/3.6/lib/python3.6/site-packages/django/core/handlers/exception.py", line 34, in inner
    response = get_response(request)
  File "/Library/Frameworks/Python.framework/Versions/3.6/lib/python3.6/site-packages/django/core/handlers/base.py", line 115, in _get_response
    response = self.process_exception_by_middleware(e, request)
  File "/Library/Frameworks/Python.framework/Versions/3.6/lib/python3.6/site-packages/django/core/handlers/base.py", line 113, in _get_response
    response = wrapped_callback(request, *callback_args, **callback_kwargs)
  File "/Users/arunbabupt/Desktop/tempo/Handwriting-System-master/main/views.py", line 29, in GeneratedImage
    testfuntion()
  File "/Users/arunbabupt/Desktop/tempo/Handwriting-System-master/static/Synthesis/demo.py", line 153, in testfuntion
    hand = Hand()
  File "/Users/arunbabupt/Desktop/tempo/Handwriting-System-master/static/Synthesis/demo.py", line 39, in __init__
    self.nn.restore()
  File "/Users/arunbabupt/Desktop/tempo/Handwriting-System-master/static/Synthesis/tf_base_model.py", line 326, in restore
    saver.restore(self.session, model_path)
  File "/Library/Frameworks/Python.framework/Versions/3.6/lib/python3.6/site-packages/tensorflow/python/training/saver.py", line 1751, in restore
    raise ValueError("Can't load save_path when it is None.")
ValueError: Can't load save_path when it is None.
[[06/03/2020 11:35:06 AM]] /Users/arunbabupt/Desktop/tempo/Handwriting-System-master/static/Synthesis/demo.py changed, reloading.
